Workbook

Sheet Caso 1
A1: Consideraciones: 1. Se tomo la variable φm=0.937-0.01746(A3/At) haciendo un cambio a la original y se itero una sola vez. 2. Se tomaron los valores de Cp ideales que calcula Hysys para el algoritmo, sin embargo, como aun no se comprende en totalidad la naturaleza del eyector en Hysys se cree que calcula con los valores reales y es por ello la discrepancia menor al 4%. 3.Se tomo el valor de w igual a 0.0229 el cual fue alcanzado por lo investigadores y la eficiencia del eyector se mantuvo en 100% en Hysys. 4. Para el simulador se tomo la variable de tamaño del nozzle primario como dpl y dt para el nozzle secundario. 5. Se itero solo una vez debido a que no fue posible alcanzar la presión deseada en un numero de iteraciones 6. Para aquellos casos en donde no se alcanza la presion desea se reinyecta en otros cabezales de gas en este caso el de 60 psi
K6: Fluido Primario | M6: Fluido Secundario | O6: Fluido Descarga
K7: Gas Natural | M7: Gas de TEA | O7: Gas de Salida
K8: Compuestos | L8: Fracción Molar | M8: Compuestos | N8: Fracción Molar | O8: Compuestos | P8: Fracción Molar
K9: methane | L9: 0.18642547 | M9: methane | N9: 0.115 | O9: methane | P9: 0.1857432
K10: ethane | L10: 0.11498025 | M10: ethane | N10: 0.0425 | O10: ethane | P10: 0.1142765
B11: Resultados | G11: Resultados | K11: propane | L11: 0.08547243 | M11: propane | N11: 0.126 | O11: propane | P11: 0.086003286
B12: Dimensiones | C12: Eyector 1 Rama 1 | D12: Eyector 1 Rama 2 | G12: Propiedades | H12: Eyector 1 | I12: Eyector2 | K12: butane | L12: 0.05623412 | M12: butane | N12: 0.136 | O12: butane | P12: 0.057176232
B13: dt [mm] | C13: 14.038437 | D13: 14.038437 | G13: PMp [Kg/Kmol] | H13: 18.415576 | I13: 18.415576 | K13: isobutane | L13: 0.01690103 | M13: isobutane | N13: 0.0834 | O13: isobutane | P13: 0.017658952
B14: dpl [mm] | C14: 37.33355 | D14: 37.33355 | G14: PMs [Kg/Kmol] | H14: 38.401404 | I14: 38.401404 | K14: ethylene | L14: 0 | M14: ethylene | N14: 0.0085 | O14: ethylene | P14: 9.4897394e-05
B15: d3 [mm] | C15: 36.554853 | D15: 36.554853 | G15: Pp [Mpa] | H15: 3.68 | I15: 3.68 | K15: propylene | L15: 0 | M15: propylene | N15: 0.0428 | O15: propylene | P15: 0.00047783629
B16: ds [mm] | C16: 9.9935706 | D16: 9.9935706 | G16: Tp [K] | H16: 323.15 | I16: 323.15 | K16: isopentane | L16: 0.03553861 | M16: isopentane | N16: 0.118 | O16: isopentane | P16: 0.036491836
B17: Pc algoritmo | C17: 0.38021627 | D17: 0.38021627 | E17: 0.53 | G17: Ps [Mpa] | H17: 0.111 | I17: 0.111 | K17: hydrogen | L17: 0.49017537 | M17: hydrogen | N17: 0.124 | O17: hydrogen | P17: 0.4865368
B18: Pc Hysys | C18: 0.36855699 | D18: 0.36855699 | E18: 0.625 | G18: Ts [K] | H18: 313.15 | I18: 313.15 | K18: nitrogen | L18: 0.01336375 | M18: nitrogen | N18: 0.152 | O18: nitrogen | P18: 0.014923797
B19: mp [Kg/s] | C19: 0.89624918 | D19: 0.89624918 | G19: Cpp [KJ/KgK] | H19: 2.5351854 | I19: 2.5351854 | K19: carbon monoxide | L19: 0 | M19: carbon monoxide | N19: 0.01266 | O19: carbon monoxide | P19: 0.0001413413
B20: ms [Kg/s] | C20: 0.020524106 | D20: 0.020524106 | G20: Cps [KJ/KgK] | H20: 1.747286 | I20: 1.747286 | K20: carbon dioxide | L20: 0 | M20: carbon dioxide | N20: 0.0028 | O20: carbon dioxide | P20: 3.1260318e-05
B21: ω | C21: =C20/C19 -> 0.0229 | D21: =D20/D19 -> 0.0229 | G21: Rp [KJ/KgK] | H21: 0.45127024 | I21: 0.45127024 | K21: hydrogen sulfide | L21: 0 | M21: oxygen | N21: 0.0071 | O21: oxygen | P21: 0.00036367268
B22: %E | C22: =ABS(C17-C18)/C17 -> 0.030664869 | D22: =ABS(D17-D18)/D17 -> 0.030664885 | G22: Rs [KJ/KgK] | H22: 0.2165025 | I22: 0.2165025 | K22: oxygen | L22: =0.028735/100 -> 0.00028735 | M22: hydrogen sulfide | N22: 0.0072 | O22: hydrogen sulfide | P22: 8.0383675e-05
E23: =D18/0.111 -> 3.3203332 | F23: =D17/0.111 -> 3.4253718 | G23: ϒp | H23: =H19/(H19-H21) -> 1.2165492 | I23: =I19/(I19-I21) -> 1.2165492 | K23: Total | L23: =SUM(L9:L22) -> 0.99937838 | M23: Total | N23: =SUM(N9:N22) -> 0.97796 | O23: Total | P23: =SUM(P9:P22) -> 1
C24: =AVERAGE(C21:D21) -> 0.0229 | D24: =AVERAGE(C22:D22) -> 0.030664877 | G24: ϒs | H24: =H20/(H20-H22) -> 1.1414325 | I24: =I20/(I20-I22) -> 1.1414325
B26: =C19*2 -> 1.7924984 | C26: 0.36769781 | E26: =C20*2 -> 0.041048212 | G26: =C17/0.1 -> 3.8021627 | H26: =G26/G27 -> 34.253718
B27: =C20*2 -> 0.041048212 | C27: =ABS(C17-C26)/C17 -> 0.032924585 | E27: =C19*2 -> 1.7924984 | G27: 0.111 | I27: 0.53
B28: =B27/B26 -> 0.0229 | E28: =E26/E27 -> 0.0229
G29: 0.38021627 | H29: =G29/G30 -> 3.4253718
C30: 0.17273275 | E30: 0.0001 | G30: 0.111
C31: =C30*2 -> 0.34546551 | F31: 0.3472669
C32: =C20*2 -> 0.041048212 | D32: =C32/C31 -> 0.11882 | F32: =F31/0.111 -> 3.1285306
C36: 22959.241
A39: Para aquellos casos en donde no se alcanza la presion desea se reinyecta en otros cabezales de gas
A40: Se mantiene la razon de arrastre de los inveestigadores y desde el punto de vista operativo se escoge el cabezal
C44: 0.041048212
D47: # ramas | E47: #equipos por rama | F47: Dimensiones eyectores [mm] | G47: Pcalgoritmo [Mpa] | H47: |Pcalgoritmo-PcHysys| [%] | I47: ωCalculado | J47: |ωcalculado -ωpaper| [%]
C48: Caso 1 | D48: 2 | E48: 1 | F48: 14-37 | G48: 0.38021627 | H48: 0.030664869 | I48: 0.0229 | J48: 0
C49: Caso 5 | D49: 3 | E49: 1 | F49: ="11-29" -> 11-29 | G49: 0.3785786 | H49: 0.030238365 | I49: 0.0246 | J49: 0

Sheet Caso 2
A1: Consideraciones: 1. Se tomo la variable φm=0.937-0.01746(A3/At) haciendo un cambio a la original para todas las iteraciones, sin embargo, con el fin de mantener la variable de diseño constante (Radio de compresión) se ajusto su valor en un rango no superior al 4% de diferencia como se evidencia en los resultados. 2. Se tomaron los valores de Cp ideales que calcula Hysys para el algoritmo, sin embargo, como aun no se comprende en totalidad la naturaleza del eyector en Hysys se cree que calcula con los valores reales y es por ello la discrepancia menor al 10%. 3.Se tomo el valor de w igual a 0.04 inicial y la eficiencia del eyector se mantuvo en 100% en Hysys. 4. Para el simulador se tomo la variable de tamaño del nozzle primario como dpl y dt para el nozzle secundario. 5. Se obto por mantener un flujo de gas natural bajo manteniendo el radio de compresión constante. Por ello el caso 3 fue la elección con un Qm modificado que dio una diferencia menor al 4%
B11: RC1=RC2 | C11: Eyectores | D11: Ps | E11: Pc | F11: Rc
B12: RC=Pc/Ps | C12: 1 | D12: 0.1 | E12: =SQRT(D12*E13) -> 0.23021729 | F12: =E12/D12 -> 2.3021729 | G12: =E12-D12 -> 0.13021729 | H12: =C25/D12 -> 2.6908294
B13: Ps1 = 0.111 | C13: 2 | D13: =E12 -> 0.23021729 | E13: 0.53 | F13: =E13/D13 -> 2.3021729 | G13: =E13-D13 -> 0.29978271 | H13: =D25/C25 -> 1.9755652
B14: Pc2 = 0.527
B16: Caso 1 Psalida 0.625, Radio de compresión 2.5 dpl primario ds secundario variando Qm
B18: Resultados dpl y ds | J18: Resultados
B19: Dimensiones | C19: Eyector 1 | D19: Eyector 2 Qm iterado | E19: Eyector 2 Qm = 0.83 | F19: Eyector 2 Qm = 0.80 | G19: Eyector 2 Qm = 0.78 | J19: Propiedades | K19: Eyector 1 | L19: Eyector2
B20: dt [mm] | C20: 5.5384198 | D20: 13.18651 | E20: 13.651479 | F20: 18.782678 | J20: PMp [Kg/Kmol] | K20: 18.415576 | L20: 18.415576
B21: dpl [mm] | C21: 15.305922 | D21: 25.734254 | E21: 26.641669 | F21: 36.655508 | J21: PMs [Kg/Kmol] | K21: 38.401404 | L21: 19.732777
B22: d3 [mm] | C22: 17.850705 | D22: 31.969986 | E22: 32.620683 | F22: 40.306772 | J22: Pp [Mpa] | K22: 3.68 | L22: 3.68
B23: ds [mm] | C23: 10.53561 | D23: 20.92275 | E23: 20.92275 | F23: 20.92275 | G23: 20.92275 | J23: Tp [K] | K23: 323.15 | L23: 323.15
B24: Pc algoritmo | C24: 0.25009654 | D24: 0.62509908 | E24: 0.6250971 | F24: 0.62509665 | J24: Ps [Mpa] | K24: 0.1 | L24: =C25 -> 0.26908294
B25: Pc Hysys | C25: 0.26908294 | D25: 0.53159091 | E25: 0.5394942 | F25: 0.60594192 | J25: Ts [K] | K25: 313.05 | L25: 310.97
B26: mp [Kg/s] | C26: 0.13949641 | D26: 0.79077146 | E26: 0.84752138 | F26: 1.6043765 | J26: Cpp [KJ/KgK] | K26: 2.5351854 | L26: 2.5351854
B27: ms [Kg/s] | C27: 0.020524106 | D27: 0.16002051 | E27: 0.16002051 | F27: 0.16002051 | G27: 0.16002051 | J27: Cps [KJ/KgK] | K27: 1.7468897 | L27: 2.3922553
B28: ω | C28: =C27/C26 -> 0.14713 | D28: =D27/D26 -> 0.20236 | E28: =E27/E26 -> 0.18881 | F28: =F27/F26 -> 0.09974 | G28: =G27/G26 -> #DIV/0! | J28: Rp [KJ/KgK] | K28: 0.45127024 | L28: 0.45127024
B29: %E | C29: =ABS(C24-C25)/C24 -> 0.075916277 | D29: =ABS(D24-D25)/D24 -> 0.14958936 | E29: =ABS(E24-E25)/E24 -> 0.13694336 | F29: =ABS(F24-F25)/F24 -> 0.030642825 | G29: =ABS(G24-G25)/G24 -> #DIV/0! | J29: Rs [KJ/KgK] | K29: 0.2165025 | L29: 0.42132945
J30: ϒp | K30: =K26/(K26-K28) -> 1.2165492 | L30: =L26/(L26-L28) -> 1.2165492
B31: w | C31: =($C$27*2)/($C$26*2+D26*2) -> 0.022062577 | E31: =($C$27*2)/($C$26*2+E26*2) -> 0.020794059 | F31: =($C$27*2)/($C$26*2+F26*2) -> 0.011769267 | J31: ϒs | K31: =K27/(K27-K29) -> 1.1414691 | L31: =L27/(L27-L29) -> 1.2137723
B32: %E | C32: =AVERAGE(C29:D29) -> 0.11275282 | E32: =AVERAGE(C29,E29) -> 0.10642982 | F32: =AVERAGE(C29,F29) -> 0.053279551
B34: mp investigadores | C34: mp caso a | E34: mp caso b | F34: mp caso c
B35: =(C27*2)/B37 -> 0.87151194 | C35: =C26*2+D26*2 -> 1.8605357 | E35: =C26*2+E26*2 -> 1.9740356 | F35: =C26*2+F26*2 -> 3.4877458
B36: w investigadores | C36: %E w | E36: %E w | F36: %E w | H36: =C27*2 -> 0.041048212
B37: 0.0471 | C37: =ABS(B37-C31)/B37 -> 0.53158011 | E37: =ABS(B37-E31)/B37 -> 0.55851255 | F37: =ABS(B37-F31)/B37 -> 0.75012172
B41: Caso 2. Presion de salida 0.625, Radio de compresion 2.5 dpl primario y dt secundario
B43: Resultados dpl y dt
B44: Dimensiones | C44: Eyector 1 | D44: Eyector 2 Qm iterado | E44: Eyector 2 Qm = 0.83 | F44: Eyector 2 Qm = 0.8 | G44: Eyector 2 Qm = 0.81 | H44: Eyector 2 Qm = 0.814 | I44: Eyector 2 Qm = 0.82 | J44: Eyector 2 Qm = 0.825 | M44: Resultados
B45: dt [mm] | C45: 5.5384198 | D45: 15.726075 | E45: 15.97602 | F45: 24.446445 | G45: 20.400133 | H45: 19.246188 | I45: 18.241217 | J45: 17.229424 | M45: Propiedades | N45: Eyector 1 | O45: Eyector2
B46: dpl [mm] | C46: 15.305922 | D46: 33.977358 | E46: 34.517384 | F46: 52.818371 | G46: 44.07601 | H46: 41.582826 | I46: 39.411513 | J46: 37.225457 | M46: PMp [Kg/Kmol] | N46: 18.415576 | O46: 18.415576
B47: d3 [mm] | C47: 17.850705 | D47: 38.636897 | E47: 39.058913 | F47: 54.244279 | G47: 46.813899 | H47: 44.746257 | I47: 43.232937 | J47: 41.479841 | M47: PMs [Kg/Kmol] | N47: 38.401404 | O47: 19.732777
B48: ds [mm] | C48: 10.53561 | D48: 20.999209 | E48: 20.999209 | F48: 20.999209 | G48: 20.999209 | H48: 20.999209 | M48: Pp [Mpa] | N48: 3.68 | O48: 3.68
B49: Pc algoritmo | C49: 0.25009654 | D49: 0.62509302 | E49: 0.62509984 | F49: 0.6250992 | G49: 0.62509595 | H49: 0.62509976 | I49: 0.62509435 | J49: 0.62509922 | M49: Tp [K] | N49: 323.15 | O49: 323.15
B50: Pc Hysys | C50: 0.25012786 | D50: 0.56920733 | E50: 0.57391987 | F50: 0.66420273 | G50: 0.6334436 | H50: 0.62136069 | I50: 0.60345806 | J50: 0.58891462 | M50: Ps [Mpa] | N50: 0.1 | O50: =C50 -> 0.25012786
B51: mp [Kg/s] | C51: 0.13949641 | D51: 1.4358054 | E51: 1.4818086 | F51: 3.4696555 | G51: 2.4161334 | H51: 2.1505243 | I51: 1.9318018 | J51: 1.723441 | M51: Ts [K] | N51: 313.05 | O51: 310.88
B52: ms [Kg/s] | C52: 0.020524106 | D52: 0.16002051 | E52: 0.16002051 | F52: 0.16002051 | G52: 0.16002051 | H52: 0.16002051 | I52: 0.16002051 | J52: 0.16002051 | M52: Cpp [KJ/KgK] | N52: 2.5351854 | O52: 2.5351854
B53: ω | C53: =C52/C51 -> 0.14713 | D53: =D52/D51 -> 0.11145 | E53: =E52/E51 -> 0.10799 | F53: =F52/F51 -> 0.04612 | G53: =G52/G51 -> 0.06623 | H53: =H52/H51 -> 0.07441 | I53: =I52/I51 -> 0.08283485 | J53: =J52/J51 -> 0.092849427 | M53: Cps [KJ/KgK] | N53: 1.7468897 | O53: 2.3919394
B54: %E | C54: =ABS(C49-C50)/C49 -> 0.00012519976 | D54: =ABS(D49-D50)/D49 -> 0.089403789 | E54: =ABS(E49-E50)/E49 -> 0.081874878 | F54: =ABS(F49-F50)/F49 -> 0.062555725 | G54: =ABS(G49-G50)/G49 -> 0.013354193 | H54: =ABS(H49-H50)/H49 -> 0.0059815593 | I54: =ABS(I49-I50)/I49 -> 0.034612842 | J54: =ABS(J49-J50)/J49 -> 0.057886175 | M54: Rp [KJ/KgK] | N54: 0.45127024 | O54: 0.45127024
B55: Qm | D55: 0.8316079 | E55: =ABS($D$55-0.83)/$D$55 -> 0.0019334861 | F55: =ABS($D$55-0.8)/$D$55 -> 0.038008179 | G55: =ABS($D$55-0.81)/$D$55 -> 0.025983282 | H55: =ABS($D$55-0.814)/$D$55 -> 0.021173323 | I55: =ABS($D$55-0.82)/$D$55 -> 0.013958384 | J55: =ABS($D$55-0.825)/$D$55 -> 0.007945935 | M55: Rs [KJ/KgK] | N55: 0.2165025 | O55: 0.42132945
C56: =C50/D12 -> 2.5012786 | D56: =D50/C50 -> 2.2756655 | E56: =E50/C50 -> 2.294506 | F56: =F50/C50 -> 2.6554529 | G56: =G50/C50 -> 2.5324792 | H56: =H50/C50 -> 2.4841723 | I56: =I50/C50 -> 2.4125984 | J56: =J50/C50 -> 2.3544543 | M56: ϒp | N56: =N52/(N52-N54) -> 1.2165492 | O56: =O52/(O52-O54) -> 1.2165492
...

Sheet Caso 3
A1: Consideraciones: 1. Se tomo la variable φm=0.937-0.01746(A3/At) haciendo un cambio a la original para todas las iteraciones, sin embargo, con el fin de mantener la variable de diseño constante (Radio de compresión) se ajusto su valor en un rango no superior al 7% de diferencia como se evidencia en los resultados. 2. Se tomaron los valores de Cp ideales que calcula Hysys para el algoritmo, sin embargo, como aun no se comprende en totalidad la naturaleza del eyector en Hysys se cree que calcula con los valores reales y es por ello la discrepancia menor al 2%. 3.Se tomo el valor de w igual a 0.04 inicial y la eficiencia del eyector se mantuvo en 100% en Hysys. 4. Para el simulador se tomo la variable de tamaño del nozzle primario como dpl y dt para el nozzle secundario. 5. Se obto por mantener un flujo de gas natural bajo manteniendo el radio de compresión constante por ello se modifico el Qm
B11: Arreglo 3 eyectores, 1 rama, RC constante para cada eyector | H11: RC1 | I11: ='Caso 1'!I17/'Caso 1'!H17 -> 1
B12: RC1=RC2=RC3 | C12: Eyectores | D12: Ps | E12: Pc | F12: Rc | H12: RC2 | I12: =#REF!/'Caso 1'!I17 -> #REF!
B13: RC=Pc/Ps | C13: 1 | D13: 0.1 | E13: =(E15*D13*D13)^(1/3) -> 0.17435134 | F13: =E13/D13 -> 1.7435134 | H13: RC3 | I13: =0.4128/#REF! -> #REF! | L13: 21038.741
B14: Ps1 = 0.111 | C14: 2 | D14: =E13 -> 0.17435134 | E14: =E13^2/D13 -> 0.3039839 | F14: =E14/D14 -> 1.7435134
B15: Pc3 = | C15: 3 | D15: =E14 -> 0.3039839 | E15: 0.53 | F15: =E15/D15 -> 1.7435134 | I15: mp total | J15: 5.8440948 | L15: w investigadores | M15: 0.0494
I16: ms total | J16: =C26*F17 -> 0.041048212 | L16: %E | M16: =ABS(M15-J17)/M15 -> 0.85781622
E17: Ramas | F17: 2 | I17: w total | J17: =J16/J15 -> 0.0070238787
B18: Resultados dpl y dt
B19: Dimensiones | C19: Eyector 1 | D19: Eyector 1 Qm=0.669 | E19: Eyector 2 Qm iterado | F19: Eyector 2 Qm = 0.70 | G19: Eyector 2 Qm =0.71 | H19: Eyector 2 Qm = 0.701 | I19: Eyector 3 iterado | J19: Eyector 3 Qm = 0.78 | K19: Eyector 3 Qm = 0.76 | L19: Eyector 3 Qm = 0.748 | N19: Resultados
B20: dt [mm] | C20: 3.7346711 | D20: 4.057719 | E20: 7.6217017 | F20: 8.8335045 | G20: 8.2782087 | H20: 8.7737142 | I20: 16.86346 | J20: 18.777727 | K20: 21.325794 | L20: 22.973823 | N20: Propiedades | O20: Eyector 1 | P20: Eyector2 | Q20: Eyector 3
B21: dpl [mm] | C21: 10.3211 | D21: 11.213872 | E21: 17.336026 | F21: 21.912725 | G21: 20.535237 | H21: 21.764407 | I21: 31.62148 | J21: 35.211014 | K21: 39.989016 | L21: 43.079314 | N21: PMp [Kg/Kmol] | O21: 18.415576 | P21: 18.415576 | Q21: 18.415576
B22: d3 [mm] | C22: 14.327925 | D22: 14.911401 | E22: 25.65177 | F22: 28.601386 | G22: 27.67907 | H22: 28.500672 | I22: 47.230119 | J22: 49.42381 | K22: 52.538352 | L22: 54.654945 | N22: PMs [Kg/Kmol] | O22: 38.401404 | P22: 20.737434 | Q22: 18.785586
B23: Pc algoritmo | C23: 0.1744482 | D23: 0.1744504 | E23: 0.3040819 | F23: 0.3040814 | G23: 0.3040829 | H23: 0.304082 | I23: 0.5300972 | J23: 0.5300968 | K23: 0.5300963 | L23: 0.5300961 | N23: Pp [Mpa] | O23: 3.68 | P23: 3.68 | Q23: 3.68
B24: Pc Hysys | C24: No resolvio | D24: 0.17456207 | E24: No resolvio | F24: 0.30518235 | G24: 0.27668213 | H24: 0.30229268 | I24: 0.35076987 | J24: 0.41677851 | K24: 0.48586381 | L24: 0.52130562 | N24: Tp [K] | O24: 323.15 | P24: 323.15 | Q24: 323.15
B25: mp [Kg/s] | C25: 0.063430189 | D25: 0.074878169 | E25: 0.2641771 | F25: 0.45302377 | G25: 0.39785761 | H25: 0.44691187 | I25: 1.2932564 | J25: 1.6035309 | K25: 2.0682436 | L25: 2.4002573 | N25: Ps [Mpa] | O25: 0.1 | P25: =D24 -> 0.17456207 | Q25: =H24 -> 0.30229268
B26: ms [Kg/s] | C26: 0.020524106 | D26: 0.020524106 | E26: 0.095402276 | F26: 0.095402276 | G26: 0.095402276 | H26: 0.095402276 | I26: 0.54231414 | J26: 0.54231414 | K26: 0.54231414 | L26: 0.54231414 | N26: Ts [K] | O26: 313.05 | P26: 310.77 | Q26: 310.87
B27: ω | C27: =C26/C25 -> 0.32357 | D27: =D26/D25 -> 0.2741 | E27: =E26/E25 -> 0.36113 | F27: =F26/F25 -> 0.21059 | G27: =G26/G25 -> 0.23979 | H27: =H26/H25 -> 0.21347 | I27: =I26/I25 -> 0.41934 | J27: =J26/J25 -> 0.3382 | ... L27: =L26/L25 -> 0.22594 | N27: Cpp [KJ/KgK] | O27: 2.5351854 | P27: 2.5351854 | Q27: 2.5351854
B28: %E | C28: =ABS(C23-C24)/C23 -> #VALUE! | D28: =ABS(D23-D24)/D23 -> 0.00064010582 | E28: =ABS(E23-E24)/E23 -> #VALUE! | F28: =ABS(F23-F24)/F23 -> 0.0036205797 | G28: =ABS(G23-G24)/G23 -> 0.090109549 | H28: =ABS(H23-H24)/H23 -> 0.0058843206 | I28: =ABS(I23-I24)/I23 -> 0.33829141 | J28: =ABS(J23-J24)/J23 -> 0.21376905 | ... L28: =ABS(L23-L24)/L23 -> 0.016582798 | N28: Cps [KJ/KgK] | O28: 1.7468897 | P28: 2.3264006 | Q28: 2.4596431
C29: 0.68001598 | D29: =ABS(C29-0.669)/C29 -> 0.016199586 | E29: 0.73922335 | F29: =ABS(E29-0.7)/E29 -> 0.053060219 | G29: =ABS(E29-0.71)/E29 -> 0.039532508 | H29: =ABS(E29-0.701)/E29 -> 0.051707448 | I29: 0.80004151 | J29: =ABS($I$29-0.78)/$I$29 -> 0.025050585 | K29: =ABS($I$29-0.76)/$I$29 -> 0.050049288 | L29: =ABS($I$29-0.75)/$I$29 -> 0.06254864 | N29: Rp [KJ/KgK] | O29: 0.45127024 | P29: 0.45127024 | Q29: 0.45127024
N30: Rs [KJ/KgK] | O30: 0.2165025 | P30: 0.40091749 | Q30: 0.44257336
D31: =D24/0.1 -> 1.7456207 | F31: =F24/D24 -> 1.7482742 | G31: =G24/D24 -> 1.5850072 | H31: =H24/D24 -> 1.7317204 | I31: =I24/$Q$25 -> 1.1603651 | J31: =J24/$Q$25 -> 1.3787251 | K31: =K24/$Q$25 -> 1.6072629 | L31: =L24/$Q$25 -> 1.7245063 | N31: ϒp | O31: =O27/(O27-O29) -> 1.2165492 | P31: =P27/(P27-P29) -> 1.2165492 | Q31: =Q27/(Q27-Q29) -> 1.2165492
C32: =D25*2+H25*2+L25*2 -> 5.8440948 | N32: ϒs | O32: =O28/(O28-O30) -> 1.1414691 | P32: =P28/(P28-P30) -> 1.2082166 | Q32: =Q28/(Q28-Q30) -> 1.219414
C33: =C26*2 -> 0.041048212 | D33: =AVERAGE(D28,H28,L28) -> 0.0077024083 | F33: =AVERAGE(D29,H29,L29) -> 0.043485224 | H33: =C26*2/(D25*2+H25*2+L25*2) -> 0.0070238787
D34: =C33/C32 -> 0.0070238787
B35: Caso 2. Mantengo el radio de compresión constante con respecto al caso 2
B38: Arreglo 3 eyectores, 1 rama, RC constante para cada eyector
B39: RC1=RC2=RC3 | C39: Eyectores | D39: Ps | E39: Pc | F39: Rc
B40: RC=Pc/Ps | C40: 1 | D40: 0.0435 | E40: =(E42*D40*D40)^(1/3) -> 0.10009632 | F40: =E40/D40 -> 2.3010649
B41: Ps1 = 0.111 | C41: 2 | D41: =E40 -> 0.10009632 | E41: =E40^2/D40 -> 0.23032814 | F41: =E41/D41 -> 2.3010649
B42: Pc3 = | C42: 3 | D42: =E41 -> 0.23032814 | E42: 0.53 | F42: =E42/D42 -> 2.3010649

Sheet Caso 4
A1: Consideraciones: 1. Se tomo la variable φm=0.937-0.01746(A3/At) haciendo un cambio a la original para todas las iteraciones, sin embargo, con el fin de mantener la variable de diseño constante (Radio de compresión) se ajusto su valor en un rango no superior al 7% de diferencia como se evidencia en los resultados. 2. Se tomaron los valores de Cp ideales que calcula Hysys para el algoritmo, sin embargo, como aun no se comprende en totalidad la naturaleza del eyector en Hysys se cree que calcula con los valores reales y es por ello la discrepancia menor al 2%. 3.Se tomo el valor de w igual a 0.04 inicial y la eficiencia del eyector se mantuvo en 100% en Hysys. 4. Para el simulador se tomo la variable de tamaño del nozzle primario como dpl y dt para el nozzle secundario. 5. Se obto por mantener un flujo de gas natural bajo manteniendo el radio de compresión constante por ello se modifico el Qm
B11: Arreglo 3 eyectores, 1 rama, RC constante para cada eyector | H11: RC1 | I11: ='Caso 1'!I17/'Caso 1'!H17 -> 1
B12: RC1=RC2=RC3 | C12: Eyectores | D12: Ps | E12: Pc | F12: Rc | H12: RC2 | I12: =#REF!/'Caso 1'!I17 -> #REF!
B13: RC=Pc/Ps | C13: 1 | D13: 0.1 | E13: =SQRT(E14*D13) -> 0.15172913 | F13: =E13/D13 -> 1.5172913 | H13: RC3 | I13: =0.4128/#REF! -> #REF! | L13: 21038.741
B14: Ps1 = 0.111 | C14: 2 | D14: =E13 -> 0.15172913 | E14: =SQRT(E16*D13) -> 0.23021729 | F14: =E14/D14 -> 1.5172913
B15: Pc3 = | C15: 3 | D15: =E14 -> 0.23021729 | E15: =SQRT(E16*E14) -> 0.34930669 | F15: =E15/D15 -> 1.5172913
C16: 4 | D16: =E15 -> 0.34930669 | E16: 0.53 | F16: =E16/D16 -> 1.5172913
I17: mp total | J17: =C19*D27+C19*H27+C19*L27+C19*O27 -> 16.67568 | L17: w investigadores | M17: 0.0439
I18: ms total | J18: =C28*C19 -> 0.041048212 | L18: %E | M18: =ABS(M17-J19)/M17 -> 0.94392798
B19: Ramas | C19: 2 | I19: w total | J19: =J18/J17 -> 0.0024615615
B20: Resultados dpl y dt
B21: Dimensiones | C21: Eyector 1 | D21: Eyector 1 Qm=0.6216 | E21: Eyector 2 Qm iterado | F21: Eyector 2 Qm = 0.62 | G21: Eyector 2 Qm =0.625 | H21: Eyector 2 Qm = 0.626 | I21: Eyector 3 iterado | J21: Eyector 3 Qm = 0.70 | K21: Eyector 3 Qm = 0.68 | L21: Eyector 3 Qm = 0.686 | M21: Eyector 4 iterado | N21: Eyector 4 Qm = 0.76 | O21: Eyector 4 Qm = 0.726
B22: dt [mm] | C22: 3.3543637 | D22: 4.0470286 | E22: 6.1325766 | F22: 8.5679159 | G22: 8.24659 | H22: 8.1859267 | I22: 12.931318 | J22: 14.799643 | K22: 16.596669 | L22: 16.004204 | M22: 26.910826 | N22: 29.65136 | O22: 37.723275
B23: dpl [mm] | C23: 9.2700865 | D23: 11.184328 | E23: 13.971042 | F23: 19.519156 | G23: 18.787121 | H23: 18.64892 | I23: 28.657632 | J23: 32.798104 | K23: 36.780568 | L23: 35.467583 | M23: 51.393755 | N23: 56.627572 | O23: 67.415521
B24: d3 [mm] | C24: 13.67545 | D24: 14.891698 | E24: 23.7635 | F24: 27.00578 | G24: 26.541853 | H24: 26.455369 | I24: 44.759651 | J24: 47.21288 | K24: 49.746958 | L24: 48.894227 | M24: 80.252497 | N24: 83.311461 | O24: 90.093585
B25: Pc algoritmo | C25: 0.1518268 | D25: 0.1518285 | E25: 0.230316 | F25: 0.2303161 | G25: 0.23031626 | H25: 0.2303161 | I25: 0.3494034 | J25: 0.3494062 | K25: 0.3494043 | L25: 0.3494064 | M25: 0.5300983 | N25: 0.5300965 | O25: 0.5300969
B26: Pc Hysys | C26: No resolvio | D26: 0.17379208 | E26: No resolvio | F26: 0.25435606 | G26: 0.23772951 | H26: 0.23446656 | I26: No resolvio | J26: 0.30306728 | K26: 0.36734091 | L26: 0.34762505 | M26: No resolvio | N26: 0.4308269 | O26: 0.53039932
B27: mp [Kg/s] | C27: 0.051169549 | D27: 0.074484144 | E27: 0.17103195 | F27: 0.33384253 | G27: 0.30927163 | H27: 0.30473826 | I27: 0.97082404 | J27: 1.2716201 | K27: 1.5991779 | L27: 1.4870415 | M27: 4.2044479 | N27: 5.1043936 | O27: 6.4715762
B28: ms [Kg/s] | C28: 0.020524106 | D28: 0.020524106 | E28: 0.095008246 | F28: 0.095008246 | G28: 0.095008246 | H28: 0.095008246 | I28: 0.39974651 | J28: 0.39974651 | K28: 0.39974651 | L28: 0.39974651 | M28: 1.886788 | N28: 1.886788 | O28: 1.886788
B29: ω | C29: =C28/C27 -> 0.4011 | D29: =D28/D27 -> 0.27555 | E29: =E28/E27 -> 0.5555 | F29: =F28/F27 -> 0.28459 | G29: =G28/G27 -> 0.3072 | H29: =H28/H27 -> 0.31177 | I29: =I28/I27 -> 0.41176 | J29: =J28/J27 -> 0.31436 | ... O29: =O28/O27 -> 0.29155
B30: %E | C30: =ABS(C25-C26)/C25 -> #VALUE! | D30: =ABS(D25-D26)/D25 -> 0.14466047 | E30: =ABS(E25-E26)/E25 -> #VALUE! | F30: =ABS(F25-F26)/F25 -> 0.10437811 | G30: =ABS(G25-G26)/G25 -> 0.032187232 | H30: =ABS(H25-H26)/H25 -> 0.018020703 | I30: =ABS(I25-I26)/I25 -> #VALUE! | J30: =ABS(J25-J26)/J25 -> 0.13262192 | ... O30: =ABS(O25-O26)/O25 -> 0.0005705029
C31: 0.64679347 | D31: =ABS(C31-0.6216)/C31 -> 0.038951338 | E31: 0.67483236 | F31: =ABS(E31-0.62)/E31 -> 0.0812533 | G31: =ABS(E31-0.625)/E31 -> 0.073844053 | H31: =ABS(E31-0.626)/E31 -> 0.072362203 | I31: 0.72781429 | J31: =ABS($I$31-0.7)/$I$31 -> 0.038216188 | K31: =ABS($I$31-0.68)/$I$31 -> 0.065695726 | L31: =ABS($I$31-0.75)/$I$31 -> 0.030482655 | M31: 0.78172294 | N31: =ABS($M$31-0.76)/$M$31 -> 0.027788546 | O31: =ABS($M$31-0.726)/$M$31 -> 0.071282216
D33: =D26/0.1 -> 1.7379208 | F33: =F26/D26 -> 1.4635653 | G33: =G26/D26 -> 1.3678961 | H33: =H26/D26 -> 1.3491211 | I33: =I26/$E$44 -> #VALUE! | J33: =J26/$E$44 -> 1.2925821 | K33: =K26/$E$44 -> 1.5667092 | L33: =L26/$E$44 -> 1.482621 | M33: =M26/$E$44 -> #VALUE! | N33: =N26/$F$44 -> 1.2393437 | O33: =O26/$F$44 -> 1.5257799
C35: =D27*2+H27*2+L27*2+O27*2 -> 16.67568 | J35: =AVERAGE(D30,H30,L30,O30) -> 0.042087476 | L35: =AVERAGE(D31,H31,L31,O31) -> 0.053269603
D36: =C28*2 -> 0.041048212 | E36: =D36/C35 -> 0.0024615615
L37: =D28*2/(D27*2+H27*2+L27*2+O27*2) -> 0.0024615615
B38: Resultados
B39: Propiedades | C39: Eyector 1 | D39: Eyector2 | E39: Eyector 3 | F39: Eyector 4
B40: PMp [Kg/Kmol] | C40: 18.415576 | D40: 18.415576 | E40: 18.415576 | F40: 18.415576
B41: PMs [Kg/Kmol] | C41: 38.401404 | D41: 20.748283 | E41: 18.921171 | F41: 18.520426
B42: Pp [Mpa] | C42: 3.68 | D42: 3.68 | E42: 3.68 | F42: 3.68
B43: Tp [K] | C43: 323.15 | D43: 323.15 | E43: 323.15 | F43: 323.15
B44: Ps [Mpa] | C44: 0.1 | D44: =D26 -> 0.17379208 | E44: =H26 -> 0.23446656 | F44: =L26 -> 0.34762505
B45: Ts [K] | C45: 313.05 | D45: 310.77 | E45: 310.62 | F45: 310.98
B46: Cpp [KJ/KgK] | C46: 2.5351854 | D46: 2.5351854 | E46: 2.5351854 | F46: 2.5351854
B47: Cps [KJ/KgK] | C47: 1.7468897 | D47: 2.3257271 | E47: 2.4485846 | F47: 2.4802907
B48: Rp [KJ/KgK] | C48: 0.45127024 | D48: 0.45127024 | E48: 0.45127024 | F48: 0.45127024
B49: Rs [KJ/KgK] | C49: 0.2165025 | D49: 0.40070785 | E49: 0.43940198 | F49: 0.44890976
B50: ϒp | C50: =C46/(C46-C48) -> 1.2165492 | D50: =D46/(D46-D48) -> 1.2165492 | E50: =E46/(E46-E48) -> 1.2165492 | F50: =F46/(F46-F48) -> 1.2165492
B51: ϒs | C51: =C47/(C47-C49) -> 1.1414691 | D51: =D47/(D47-D49) -> 1.2081578 | E51: =E47/(E47-E49) -> 1.2186969 | F51: =F47/(F47-F49) -> 1.2209875

Sheet Caso 5
A1: Consideraciones: 1. Se tomo la variable φm=0.937-0.01746(A3/At) haciendo un cambio a la original y se itero una sola vez. 2. Se tomaron los valores de Cp ideales que calcula Hysys para el algoritmo, sin embargo, como aun no se comprende en totalidad la naturaleza del eyector en Hysys se cree que calcula con los valores reales y es por ello la discrepancia menor al 4%. 3.Se tomo el valor de w igual a 0.0246 el cual fue alcanzado por lo investigadores y la eficiencia del eyector se mantuvo en 100% en Hysys. 4. Para el simulador se tomo la variable de tamaño del nozzle primario como dpl y dt para el nozzle secundario. 5. Se itero solo una vez debido a que no fue posible alcanzar la presión deseada en un numero de iteraciones 6. Para aquellos casos en donde no se alcanza la presion desea se reinyecta en otros cabezales de gas en este caso el de 60 psi
B11: Resultados | G11: Resultados
B12: Dimensiones | C12: Eyector 1 Rama 1 | D12: Eyector 1 Rama 2 | E12: Eyector 1 Rama 3 | G12: Propiedades | H12: Eyector 1 | I12: Eyector2 | J12: Eyector3
B13: dt [mm] | C13: 11.059134 | D13: 11.059134 | E13: 11.059798 | G13: PMp [Kg/Kmol] | H13: 18.415576 | I13: 18.415576 | J13: 18.415576
B14: dpl [mm] | C14: 29.410451 | D14: 29.410451 | E14: 29.412215 | G14: PMs [Kg/Kmol] | H14: 38.401404 | I14: 38.401404 | J14: 38.401404
B15: d3 [mm] | C15: 28.876735 | D15: 28.876735 | E15: 28.878467 | G15: Pp [Mpa] | H15: 3.68 | I15: 3.68 | J15: 3.68
B16: Pc algoritmo | C16: 0.3785786 | D16: 0.3785786 | E16: 0.3785786 | G16: Tp [K] | H16: 323.15 | I16: 323.15 | J16: 323.15
B17: Pc Hysys | C17: 0.367131 | D17: 0.36713067 | E17: 0.367131 | G17: Ps [Mpa] | H17: 0.111 | I17: 0.111 | J17: 0.111
B18: mp [Kg/s] | C18: 0.55620328 | D18: 0.55620328 | E18: 0.55627002 | G18: Ts [K] | H18: 313.15 | I18: 313.15 | J18: 313.15
B19: ms [Kg/s] | C19: 0.013682601 | D19: 0.013682601 | E19: 0.013684243 | G19: Cpp [KJ/KgK] | H19: 2.5351854 | I19: 2.5351854 | J19: 2.5351854
B20: ω | C20: =C19/C18 -> 0.0246 | D20: =D19/D18 -> 0.0246 | E20: =E19/E18 -> 0.0246 | G20: Cps [KJ/KgK] | H20: 1.747286 | I20: 1.747286 | J20: 1.747286
B21: %E | C21: =ABS(C16-C17)/C16 -> 0.030238365 | D21: =ABS(D16-D17)/D16 -> 0.030239239 | E21: =ABS(E16-E17)/E16 -> 0.030238365 | G21: Rp [KJ/KgK] | H21: 0.45127024 | I21: 0.45127024 | J21: 0.45127024
G22: Rs [KJ/KgK] | H22: 0.2165025 | I22: 0.2165025 | J22: 0.2165025
G23: ϒp | H23: =H19/(H19-H21) -> 1.2165492 | I23: =I19/(I19-I21) -> 1.2165492 | J23: =J19/(J19-J21) -> 1.2165492
D24: =C16/H17 -> 3.410618 | G24: ϒs | H24: =H20/(H20-H22) -> 1.1414325 | I24: =I20/(I20-I22) -> 1.1414325 | J24: =J20/(J20-J22) -> 1.1414325
C25: =C18*3 -> 1.6686098
D26: =C19*3 -> 0.041047802
D27: =D26/C25 -> 0.0246
A39: Para aquellos casos en donde no se alcanza la presion desea se reinyecta en otros cabezales de gas
A40: Se mantiene la razon de arrastre de los inveestigadores y desde el punto de vista operativo se escoge el cabezal

Sheet Caso 6
A1: Consideraciones: 1. Se tomo la variable φm=0.937-0.01746(A3/At) haciendo un cambio a la original para todas las iteraciones, sin embargo, con el fin de mantener la variable de diseño constante (Radio de compresión) se ajusto su valor en un rango no superior al 7% de diferencia como se evidencia en los resultados. 2. Se tomaron los valores de Cp ideales que calcula Hysys para el algoritmo, sin embargo, como aun no se comprende en totalidad la naturaleza del eyector en Hysys se cree que calcula con los valores reales y es por ello la discrepancia menor al 2%. 3.Se tomo el valor de w igual a 0.04 inicial y la eficiencia del eyector se mantuvo en 100% en Hysys. 4. Para el simulador se tomo la variable de tamaño del nozzle primario como dpl y dt para el nozzle secundario. 5. Se obto por mantener un flujo de gas natural bajo manteniendo el radio de compresión constante por ello se modifico el Qm
B11: RC1=RC2 | C11: Eyectores | D11: Ps | E11: Pc | F11: Rc | H11: RC1 | I11: ='Caso 1'!I17/'Caso 1'!H17 -> 1
B12: RC=Pc/Ps | C12: 1 | D12: 0.1 | E12: =SQRT(D12*E13) -> 0.23021729 | F12: =E12/D12 -> 2.3021729 | H12: RC2 | I12: =#REF!/'Caso 1'!I17 -> #REF!
B13: Ps1 = 0.111 | C13: 2 | D13: =E12 -> 0.23021729 | E13: 0.53 | F13: =E13/D13 -> 2.3021729 | H13: RC3 | I13: =0.4128/#REF! -> #REF! | L13: 21038.741
B14: Pc2 = 0.527
I15: mp total | J15: 5.8440948 | L15: w investigadores | M15: 0.0494
I16: ms total | J16: =C26*F17 -> 0.041044108 | L16: %E | M16: =ABS(M15-J17)/M15 -> 0.85783044
E17: Ramas | F17: 3 | I17: w total | J17: =J16/J15 -> 0.0070231763
B18: Resultados dpl y dt
B19: Dimensiones | C19: Eyector 1 Rama 1 y 2 | D19: Eyector 1 Rama 3 | E19: Eyector 2 Qm iterado Rama 1 y 2 | F19: Eyector 2 Qm = 0.785 | G19: Eyector 2 Rama 3 Qm iterado | H19: Eyector 2 Qm = 0.785
B20: dt [mm] | C20: 4.0374961 | D20: 4.0381018 | E20: 9.9095259 | F20: 14.500163 | G20: 9.9110122 | H20: 14.502337
B21: dpl [mm] | C21: 11.157984 | D21: 11.159658 | E21: 20.553902 | F21: 30.075599 | G21: 20.55698 | H21: 30.080102
B22: d3 [mm] | C22: 13.576166 | D22: 13.578203 | E22: 25.624564 | F22: 32.912912 | G22: 25.6284 | H22: 32.917839
B23: Pc algoritmo | C23: 0.2303171 | D23: 0.2303171 | E23: 0.5300963 | F23: 0.5300991 | G23: 0.5300967 | H23: 0.5300994
B24: Pc Hysys | C24: 0.22625125 | D24: 0.22625141 | E24: 0.42236018 | F24: 0.53087727 | G24: 0.42236039 | H24: 0.53087752
B25: mp [Kg/s] | C25: 0.074133672 | D25: 0.074155915 | E25: 0.4465777 | F25: 0.95617421 | G25: 0.44671168 | H25: 0.95646106
B26: ms [Kg/s] | C26: 0.013681369 | D26: 0.013681369 | E26: 0.087815039 | F26: 0.087815039 | G26: 0.087841384 | H26: 0.087841384
B27: ω | C27: =C26/C25 -> 0.18455 | D27: =D26/D25 -> 0.18449465 | E27: =E26/E25 -> 0.19664 | F27: =F26/F25 -> 0.09184 | G27: =G26/G25 -> 0.19664 | H27: =H26/H25 -> 0.09184
B28: %E | C28: =ABS(C23-C24)/C23 -> 0.017653268 | D28: =ABS(D23-D24)/D23 -> 0.017652571 | E28: =ABS(E23-E24)/E23 -> 0.20323876 | F28: =ABS(F23-F24)/F23 -> 0.0014679683 | G28: =ABS(G23-G24)/G23 -> 0.20323898 | H28: =ABS(H23-H24)/H23 -> 0.0014678681
C29: 0.73958766 | D29: 0.73958766 | E29: 0.82025146 | F29: =ABS(E29-0.785)/E29 -> 0.042976407 | G29: 0.82025153 | H29: =ABS(E29-0.785)/E29 -> 0.042976407
C31: =C24/0.1 -> 2.2625125 | D31: =D24/0.1 -> 2.2625141 | E31: =E24/C24 -> 1.866775 | F31: =F24/C24 -> 2.3464059 | G31: =G24/D24 -> 1.8667746 | H31: =H24/D24 -> 2.3464053 | I31: =C26*3/(C25*2+D25+F25*2+H25) -> 0.013277586
C33: =C25*2+D25+F25*2+H25 -> 3.0912327 | E33: =C26*2+D26 -> 0.041044108 | F33: =AVERAGE(C28,H28) -> 0.0095605681
E34: 1
D36: # ramas | E36: #equipos por rama | F36: Dimensiones eyectores [mm] | G36: |Pcalgoritmo-PcHysys| [%] | H36: |φmIterado - φmajustado| [%] | I36: ωCalculado Global | J36: |ωcalculado -ωpaper| [%]
C37: Caso 2 | D37: 2 | E37: 2 | F37: ="4-38" -> 4-38 | G37: 0.0261 | H37: 0.0344 | I37: 0.015557456 | J37: =ABS(0.0471-I37)/0.0471 -> 0.66969307
C38: Caso 6 | D38: 3 | E38: 2 | F38: ="4-33" -> 4-33 | G38: 0.0096 | H38: 0.043 | I38: 0.013277586 | J38: =ABS(0.0407-I38)/0.0407 -> 0.67376939

Sheet Caso 7
A1: Consideraciones: 1. Se tomo la variable φm=0.937-0.01746(A3/At) haciendo un cambio a la original para todas las iteraciones, sin embargo, con el fin de mantener la variable de diseño constante (Radio de compresión) se ajusto su valor en un rango no superior al 7% de diferencia como se evidencia en los resultados. 2. Se tomaron los valores de Cp ideales que calcula Hysys para el algoritmo, sin embargo, como aun no se comprende en totalidad la naturaleza del eyector en Hysys se cree que calcula con los valores reales y es por ello la discrepancia menor al 2%. 3.Se tomo el valor de w igual a 0.04 inicial y la eficiencia del eyector se mantuvo en 100% en Hysys. 4. Para el simulador se tomo la variable de tamaño del nozzle primario como dpl y dt para el nozzle secundario. 5. Se obto por mantener un flujo de gas natural bajo manteniendo el radio de compresión constante por ello se modifico el Qm
B11: Arreglo 3 eyectores, 1 rama, RC constante para cada eyector | H11: RC1 | I11: ='Caso 1'!I17/'Caso 1'!H17 -> 1
B12: RC1=RC2=RC3 | C12: Eyectores | D12: Ps | E12: Pc | F12: Rc | H12: RC2 | I12: =#REF!/'Caso 1'!I17 -> #REF!
B13: RC=Pc/Ps | C13: 1 | D13: 0.1 | E13: =(E15*D13*D13)^(1/3) -> 0.17435134 | F13: =E13/D13 -> 1.7435134 | H13: RC3 | I13: =0.4128/#REF! -> #REF! | L13: 21038.741
B14: Ps1 = 0.111 | C14: 2 | D14: =E13 -> 0.17435134 | E14: =E13^2/D13 -> 0.3039839 | F14: =E14/D14 -> 1.7435134
B15: Pc3 = | C15: 3 | D15: =E14 -> 0.3039839 | E15: 0.53 | F15: =E15/D15 -> 1.7435134 | I15: mp total | J15: =$F$17*(D25+F25+H25) -> 5.666751 | L15: w investigadores | M15: 0.0494
I16: ms total | J16: =C26*F17 -> 0.041048211 | L16: %E | M16: =ABS(M15-J17)/M15 -> 0.85336652
E17: Ramas | F17: 3 | I17: w total | J17: =J16/J15 -> 0.0072436941
B18: Resultados dpl y dt
B19: Dimensiones | C19: Eyector 1 | D19: Eyector 1 Qm=0.669 | E19: Eyector 2 Qm iterado | F19: Eyector 2 Qm = 0.704 | G19: Eyector 3 iterado | H19: Eyector 3 Qm = 0.746
B20: dt [mm] | C20: 3.0493461 | D20: 3.3131136 | E20: 6.2230933 | F20: 7.8927787 | G20: 13.311833 | H20: 18.495523
B21: dpl [mm] | C21: 8.4271429 | D21: 9.1560881 | E21: 14.154808 | F21: 17.95261 | G21: 24.867549 | H21: 34.551089
B22: d3 [mm] | C22: 11.698702 | D22: 12.175108 | E22: 20.944585 | F22: 23.381604 | G22: 37.396837 | H22: 43.669625
B23: Pc algoritmo | C23: 0.17444819 | D23: 0.1744504 | E23: 0.30408178 | F23: 0.3040828 | G23: 0.5300972 | H23: 0.53009862
B24: Pc Hysys | C24: No resolvio | D24: 0.17456201 | E24: No resolvio | F24: 0.30373797 | G24: 0.34748868 | H24: 0.5285
B25: mp [Kg/s] | C25: 0.042286791 | D25: 0.049918778 | E25: 0.17611807 | F25: 0.28330297 | G25: 0.80587378 | H25: 1.5556953
B26: ms [Kg/s] | C26: 0.013682737 | D26: 0.013682737 | E26: 0.063601517 | F26: 0.063601517 | G26: 0.34690449 | H26: 0.34690449
B27: ω | C27: =C26/C25 -> 0.32357 | D27: =D26/D25 -> 0.2741 | E27: =E26/E25 -> 0.36113 | F27: =F26/F25 -> 0.2245 | G27: =G26/G25 -> 0.43047 | H27: =H26/H25 -> 0.22299
B28: %E | C28: =ABS(C23-C24)/C23 -> #VALUE! | D28: =ABS(D23-D24)/D23 -> 0.00063975903 | E28: =ABS(E23-E24)/E23 -> #VALUE! | F28: =ABS(F23-F24)/F23 -> 0.0011340117 | G28: =ABS(G23-G24)/G23 -> 0.3444812 | H28: =ABS(H23-H24)/H23 -> 0.0030156937
C29: 0.68001598 | D29: =ABS(C29-0.669)/C29 -> 0.016199586 | E29: 0.73922329 | F29: =ABS(E29-0.704)/E29 -> 0.047649055 | G29: 0.79920348 | H29: =ABS($G$29-0.746)/$G$29 -> 0.066570636
J30: =C26*3/(D25*3+F25*3+H25*3) -> 0.0072436941
D31: =D24/0.1 -> 1.7456201 | F31: =F24/D24 -> 1.7400005 | H31: =H24/F24 -> 1.7399866
I32: =AVERAGE(D29,F29,H29) -> 0.043473092
D33: =D25*3+F25*3+H25*3 -> 5.666751 | E33: =C26*3 -> 0.041048211 | F33: =E33/D33 -> 0.0072436941 | H33: =AVERAGE(D28,F28,H28) -> 0.0015964881
E34: Caso 3 | F34: Caso 7
D35: # ramas | E35: 2 | F35: 3
D36: #equipos por rama | E36: 3 | F36: 3
D37: Dimensiones eyectores [mm] | E37: ="4-55" -> 4-55 | F37: ="3-44" -> 3-44
D38: |Pcalgoritmo-PcHysys| [%] | E38: 0.0077 | F38: 0.0016
D39: |φmIterado - φmajustado| [%] | E39: 0.0435 | F39: 0.0435
D40: ωCalculado Global | E40: 0.0070238787 | F40: 0.0072436941
D41: |ωcalculado -ωpaper| [%] | E41: =ABS(0.0494-E40)/0.0494 -> 0.85781622 | F41: =ABS(0.0526-F40)/0.0526 -> 0.86228718

Sheet Caso 8
A1: Consideraciones: 1. Se tomo la variable φm=0.937-0.01746(A3/At) haciendo un cambio a la original para todas las iteraciones, sin embargo, con el fin de mantener la variable de diseño constante (Radio de compresión) se ajusto su valor en un rango no superior al 7% de diferencia como se evidencia en los resultados. 2. Se tomaron los valores de Cp ideales que calcula Hysys para el algoritmo, sin embargo, como aun no se comprende en totalidad la naturaleza del eyector en Hysys se cree que calcula con los valores reales y es por ello la discrepancia menor al 2%. 3.Se tomo el valor de w igual a 0.04 inicial y la eficiencia del eyector se mantuvo en 100% en Hysys. 4. Para el simulador se tomo la variable de tamaño del nozzle primario como dpl y dt para el nozzle secundario. 5. Se obto por mantener un flujo de gas natural bajo manteniendo el radio de compresión constante por ello se modifico el Qm
B11: Arreglo 3 eyectores, 1 rama, RC constante para cada eyector | H11: RC1 | I11: ='Caso 1'!I17/'Caso 1'!H17 -> 1
B12: RC1=RC2=RC3 | C12: Eyectores | D12: Ps | E12: Pc | F12: Rc | H12: RC2 | I12: =#REF!/'Caso 1'!I17 -> #REF!
B13: RC=Pc/Ps | C13: 1 | D13: 0.1 | E13: =SQRT(E14*D13) -> 0.15172913 | F13: =E13/D13 -> 1.5172913 | H13: RC3 | I13: =0.4128/#REF! -> #REF! | L13: 21038.741
B14: Ps1 = 0.111 | C14: 2 | D14: =E13 -> 0.15172913 | E14: =SQRT(E16*D13) -> 0.23021729 | F14: =E14/D14 -> 1.5172913
B15: Pc3 = | C15: 3 | D15: =E14 -> 0.23021729 | E15: =SQRT(E16*E14) -> 0.34930669 | F15: =E15/D15 -> 1.5172913
C16: 4 | D16: =E15 -> 0.34930669 | E16: 0.53 | F16: =E16/D16 -> 1.5172913
I17: mp total | J17: =C19*D27+C19*F27+C19*H27+C19*J27 -> 10.589391 | L17: w investigadores | M17: 0.0439
I18: ms total | J18: =C28*C19 -> 0.027365474 | L18: %E | M18: =ABS(M17-J19)/M17 -> 0.9411336
B19: Ramas | C19: 2 | I19: w total | J19: =J18/J17 -> 0.0025842349
B20: Resultados dpl y dt
B21: Dimensiones | C21: Eyector 1 | D21: Eyector 1 Qm=0.6216 | E21: Eyector 2 Qm iterado | F21: Eyector 2 Qm = 0.626 | G21: Eyector 3 iterado | H21: Eyector 3 Qm = 0.686 | I21: Eyector 4 iterado | J21: Eyector 4 Qm = 0.726
B22: dt [mm] | C22: 2.7388265 | D22: 3.304385 | E22: 5.007228 | F22: 6.6837815 | G22: 10.564846 | H22: 14.280817 | I22: 21.396392 | J22: 30.078658
B23: dpl [mm] | C23: 7.5689938 | D23: 9.1319658 | E23: 11.407307 | F23: 15.226778 | G23: 21.65542 | H23: 29.272276 | I23: 38.252274 | J23: 53.77435
B24: d3 [mm] | C24: 11.165958 | D24: 12.159021 | E24: 19.402814 | F24: 21.600715 | G24: 35.568317 | H24: 40.104329 | I24: 62.379572 | J24: 71.782919
B25: Pc algoritmo | C25: 0.1518268 | D25: 0.1518285 | E25: 0.2303161 | F25: 0.2303161 | G25: 0.3494059 | H25: 0.3494057 | I25: 0.5300979 | J25: 0.5300982
B26: Pc Hysys | C26: No resolvio | D26: 0.17379215 | E26: No resolvio | F26: 0.23446662 | G26: No resolvio | H26: 0.34857408 | I26: No resolvio | J26: 0.5311
B27: mp [Kg/s] | C27: 0.034113032 | D27: 0.049656095 | E27: 0.11402131 | F27: 0.20315886 | G27: 0.50759532 | H27: 0.92746467 | I27: 2.0819599 | J27: 4.1144159
B28: ms [Kg/s] | C28: 0.013682737 | D28: 0.013682737 | E28: 0.063338837 | F28: 0.063338837 | G28: 0.2664977 | H28: 0.2664977 | I28: 1.1939624 | J28: 1.1939624
B29: ω | C29: =C28/C27 -> 0.4011 | D29: =D28/D27 -> 0.27555 | E29: =E28/E27 -> 0.5555 | F29: =F28/F27 -> 0.31177 | G29: =G28/G27 -> 0.52502 | H29: =H28/H27 -> 0.28734 | I29: =I28/I27 -> 0.57348 | J29: =J28/J27 -> 0.29019
B30: %E | C30: =ABS(C25-C26)/C25 -> #VALUE! | D30: =ABS(D25-D26)/D25 -> 0.1446609 | E30: =ABS(E25-E26)/E25 -> #VALUE! | F30: =ABS(F25-F26)/F25 -> 0.018020985 | G30: =ABS(G25-G26)/G25 -> #VALUE! | H30: =ABS(H25-H26)/H25 -> 0.0023800979 | I30: =ABS(I25-I26)/I25 -> #VALUE! | J30: =ABS(J25-J26)/J25 -> 0.0018898385
C31: 0.64679347 | D31: =ABS(C31-0.6216)/C31 -> 0.038951338 | E31: 0.67483245 | F31: =ABS(E31-0.626)/E31 -> 0.072362327 | G31: 0.73910058 | H31: =ABS($G$31-0.686)/$G$31 -> 0.071844858 | I31: 0.7885952 | J31: =ABS($I$31-0.726)/$I$31 -> 0.079375581
D33: =D26/0.1 -> 1.7379215 | F33: =F26/D26 -> 1.3491209 | G33: =G26/#REF! -> #VALUE! | H33: =H26/#REF! -> #REF! | I33: =I26/#REF! -> #VALUE! | J33: =J26/#REF! -> #REF!
D35: =D27*3+F27*3+H27*3+J27*3 -> 15.884087 | E35: =C28*3 -> 0.041048211
D36: =E35/D35 -> 0.0025842349 | F36: Caso 4 | G36: Caso 8 | H36: =AVERAGE(D30,F30,H30,J30) -> 0.041737956 | I36: =AVERAGE(D31,F31,H31,J31) -> 0.065633526
E37: # ramas | F37: 2 | G37: 3
E38: #equipos por rama | F38: 4 | G38: 4 | I38: =C28*3/(D27*3+F27*3+H27*3+J27*3) -> 0.0025842349
E39: Dimensiones eyectores [mm] | F39: ="4-91" -> 4-91 | G39: ="3-72" -> 3-72
E40: |Pcalgoritmo-PcHysys| [%] | F40: 0.0421 | G40: 0.0417
E41: |φmIterado - φmajustado| [%] | F41: 0.0533 | G41: 0.0656
E42: ωCalculado Global | F42: 0.0024615615 | G42: 0.0025842349
E43: |ωcalculado -ωpaper| [%] | F43: =ABS(0.0439-F42)/0.0439 -> 0.94392798 | G43: =ABS(0.0538-G42)/0.0538 -> 0.95196589

Sheet Caso Parcial
A1: Consideraciones: 1. Se tomo la variable φm=0.937-0.01746(A3/At) haciendo un cambio a la original para todas las iteraciones, sin embargo, con el fin de mantener la variable de diseño constante (Radio de compresión) se ajusto su valor en un rango no superior al 4% de diferencia como se evidencia en los resultados. 2. Se tomaron los valores de Cp ideales que calcula Hysys para el algoritmo, sin embargo, como aun no se comprende en totalidad la naturaleza del eyector en Hysys se cree que calcula con los valores reales y es por ello la discrepancia menor al 10%. 3.Se tomo el valor de w igual a 0.04 inicial y la eficiencia del eyector se mantuvo en 100% en Hysys. 4. Para el simulador se tomo la variable de tamaño del nozzle primario como dpl y dt para el nozzle secundario. 5. Se Tomo la curva de flujo vs presión de salida de los investigadores, se calculo en primera instancia una presión deseable de los investigadores y despues se calculo un radio con base en el flujo manejado como se evidencia en el caso 1. El caso 2 se da ya que no se puede llevar el proceso a un radio de compresión ni de 3 ni de 2.5
B11: RC1=RC2 | C11: Eyectores | D11: Ps | E11: Pc | F11: Rc
B12: RC=Pc/Ps | C12: 1 | D12: 0.1 | E12: =SQRT(E13*D12) -> 0.20597671 | F12: =E12/D12 -> 2.0597671 | G12: =E12-D12 -> 0.10597671 | H12: =C27/D12 -> 1.945703
B13: Ps1 = 0.111 | C13: 2 | D13: =E12 -> 0.20597671 | E13: =SQRT(E15*D12) -> 0.42426407 | F13: =E13/D13 -> 2.0597671 | G13: =E13-D13 -> 0.21828735 | H13: =D27/C27 -> 1.705609 | K13: =0.37/1.06 -> 0.3490566
B14: Pc2 = 0.527 | C14: 3 | D14: =E13 -> 0.42426407 | E14: =SQRT(E15*E13) -> 0.87388519 | F14: =E14/D14 -> 2.0597671
C15: 4 | D15: =E14 -> 0.87388519 | E15: 1.8 | F15: =E15/D15 -> 2.0597671
I16: =5.13*0.35 -> 1.7955
H17: =2*0.1 -> 0.2
B19: Caso 1 Radio de compresión 2.1 dpl primario dt secundario variando Qm
B21: Resultados dpl y ds
B22: Dimensiones | C22: Eyector 1 | D22: Eyector 2 Qm iterado | E22: Eyector 2 Qm = 0.76 | F22: Eyector 2 Qm = 0.765 | G22: Eyector 3 Qm iterado | H22: Eyector 3 Qm=0.81
B23: dt [mm] | C23: 3.5572331 | D23: 8.1811636 | E23: 11.167024 | F23: 10.542557 | G23: 22.197879 | H23: 34.131812
B24: dpl [mm] | C24: 9.8307343 | D24: 17.900906 | E24: 24.434159 | F24: 23.067786 | G24: 37.246195 | H24: 57.270342
B25: d3 [mm] | C25: 12.633286 | D25: 23.406112 | E25: 28.156228 | F25: 27.11636 | G25: 47.576966 | H25: 62.715493
B26: Pc algoritmo | C26: 0.2060762 | D26: 0.4243605 | E26: 0.4243614 | F26: 0.4243634 | G26: 0.8739847 | H26: 0.87398384
B27: Pc Hysys | C27: 0.1945703 | D27: 0.33186086 | E27: 0.43363944 | F27: 0.41819952 | G27: 0.67708727 | H27: 0.84310933
B28: mp [Kg/s] | C28: 0.057546105 | D28: 0.30438373 | E28: 0.56710858 | F28: 0.50545584 | G28: 2.2408575 | H28: 5.2979759
B29: ms [Kg/s] | C29: 0.013682737 | D29: 0.071228837 | E29: 0.071228837 | F29: 0.071228837 | G29: 0.57668468 | H29: 0.57668468
B30: ω | C30: =C29/C28 -> 0.23777 | D30: =D29/D28 -> 0.23401 | E30: =E29/E28 -> 0.1256 | F30: =F29/F28 -> 0.14092 | G30: =G29/G28 -> 0.25735 | H30: =H29/H28 -> 0.10885
B31: %E | C31: =ABS(C26-C27)/C26 -> 0.05583321 | D31: =ABS(D26-D27)/D26 -> 0.2179742 | E31: =ABS(E26-E27)/E26 -> 0.021863537 | F31: =ABS(F26-F27)/F26 -> 0.014525002 | G31: =ABS(G26-G27)/G26 -> 0.22528705 | H31: =ABS(H26-H27)/H26 -> 0.035326183
B32: Qm | C32: 0.71678227 | D32: 0.7940867 | E32: =ABS(D32-0.76)/D32 -> 0.042925669 | F32: =ABS(D32-0.765)/D32 -> 0.036629127 | G32: 0.85679254 | H32: =ABS(G32-0.81)/G32 -> 0.054613616
B34: w | C34: =($C$29*3)/($C$28*3+F28*3+H28*3) -> 0.0023345485
B35: %E | C35: =AVERAGE(C31,F31,H31) -> 0.035228132 | E35: =AVERAGE(C31,F31,H31) -> 0.035228132
B37: mp investigadores | C37: mp caso a
B38: =(C29*3)/B40 -> 0.78038426 | C38: =C28*3+F28*3+H28*3 -> 17.582934
B39: w investigadores | C39: %E w
B40: 0.0526 | C40: =ABS(B40-C34)/B40 -> 0.95561695
B45: Caso 2 Radio de compresión 2.3 dpl primario dt secundario variando Qm
B47: Eyectores | C47: Ps | D47: Pc | E47: Rc
B48: 1 | C48: 0.1 | D48: =SQRT(D49*C48) -> 0.23003266 | E48: =D48/C48 -> 2.3003266
B49: 2 | C49: =D48 -> 0.23003266 | D49: =SQRT(D51*C48) -> 0.52915026 | E49: =D49/C49 -> 2.3003266
B50: 3 | C50: =D49 -> 0.52915026 | D50: =SQRT(D51*D49) -> 1.2172184 | E50: =D50/C50 -> 2.3003266
B51: 4 | C51: =D50 -> 1.2172184 | D51: 2.8 | E51: =D51/C51 -> 2.3003266
B53: Resultados dpl y dt | K53: Mass Flow | L53: Radio
B54: Dimensiones | C54: Eyector 1 | D54: Eyector 2 Qm iterado | E54: Eyector 2 Qm = 0.8 | F54: Eyector 2 Qm = 0.786 | G54: Eyector 3 Qm iterado | H54: Eyector 3 Qm=0.85 | I54: Eyector 3 Qm=0.84 | K54: 100 | L54: =0.0000002*(K54^2)-0.002*K54+5.3266 -> 5.1286
B55: dt [mm] | C55: 4.0335474 | D55: 9.8931246 | E55: 11.898953 | F55: 14.208708 | G55: 40.445521 | H55: 74.865244 | I55: 129.34304 | K55: 500 | L55: =0.0000002*(K55^2)-0.002*K55+5.3266 -> 4.3766
B56: dpl [mm] | C56: 11.147072 | D56: 20.527425 | E56: 24.689355 | F56: 29.481907 | G56: 62.861694 | H56: 116.3579 | I56: 201.02899 | K56: 600 | L56: =0.0000002*(K56^2)-0.002*K56+5.3266 -> 4.1986
B57: d3 [mm] | C57: 13.568481 | D57: 25.602131 | E57: 28.670854 | F57: 32.431193 | G57: 70.184917 | H57: 115.63092 | I57: 192.45851 | K57: 1000 | L57: =0.0000002*(K57^2)-0.002*K57+5.3266 -> 3.5266
B58: Pc algoritmo | C58: 0.2301288 | D58: 0.52924719 | E58: 0.5292501 | F58: 0.5292475 | G58: 1.2173083 | H58: 1.2171227 | I58: 1.2171246 | K58: 1500 | L58: =0.0000002*(K58^2)-0.002*K58+5.3266 -> 2.7766
B59: Pc Hysys | C59: 0.22601562 | D59: 0.42162569 | E59: 0.48234018 | F59: 0.52632016 | G59: 0.97720568 | H59: 1.1034621 | I59: 1.1433143 | K59: 2000 | L59: 2.3
...
